Workbook

Sheet Assumptions
A1: ClinicalHours — Model Assumptions
A2: Assumption | B2: Value | C2: Rationale / Source
A3: MARKET SIZING — FOR REFERENCE
A4: TAM (combined) | B4: 24900000 | C4: 32,380 clinic locations × $750 + 191,000 students × 5% × $60 — see appendix
A5: SAM (combined) | B5: 4400000 | C5: 17,600 clinic locations × 30% × $750 + 133,000 students × 5% × $60
A6: SOM (combined, Texas Year 1) | B6: 619200 | C6: 1,250 TX sites × 60% × $750 + 18,900 TX students × 5% × $60
A7: CLINIC SIDE
A8: Addressable TX clinic sites (Y1-Y2) | B8: 1250 | C8: 700 FQHC sites (TX DSHS) + 550 free clinics (Free Clinic Directory)
A9: Addressable national clinic sites (Y3+) | B9: 17600 | C9: 16,200 FQHC sites (HRSA) + 1,400 free clinics (NAFC)
A10: Clinic close rate Y1 | B10: 0.01 | C10: Conservative; 1 confirmed partner at launch (BCS Free Health)
A11: Clinic close rate Y2 | B11: 0.04 | C11: Grows with product proof points and active outreach
A12: Clinic close rate Y3 | B12: 0.03 | C12: National expansion opens cold market; lower initial close rate
A13: Clinic close rate Y4 | B13: 0.08 | C13: Network effect + referrals compound close rate nationally
A14: Clinic close rate Y5 | B14: 0.1 | C14: Established brand; referral flywheel at scale
A15: Annual clinic churn rate | B15: 0.1 | C15: Standard SaaS churn for small-org buyer segment
A16: Clinic price Y1-Y2 ($/site/yr) | B16: 750 | C16: Below $1K threshold; eases buy decision for smaller clinics
A17: Clinic price Y3+ ($/site/yr) | B17: 1000 | C17: Price increase as product matures and value is proven
A18: Willingness to pay (SOM basis) | B18: 0.6 | C18: 60% of TX sites willing to pay; 40% too small or unwilling at $750
A19: STUDENT SIDE
A20: Annual med school applicants (national) | B20: 54699 | C20: AAMC 2025 Applicant and Matriculant Data
A21: Average pre-med pipeline years | B21: 3.5 | C21: Average time as serious pre-med before applying
A22: National serious pre-med students | B22: 191000 | C22: 54,699 × 3.5 years (rounded)
A23: Universities producing applicants (SAM) | B23: 950 | C23: AAMC institutional breakdown
A24: Reachable pre-med orgs per university | B24: 2 | C24: Average across 950 schools with active pre-med programs
A25: Active members per org | B25: 70 | C25: Conservative estimate for high-performing pre-med orgs
A26: SAM reachable students | B26: 133000 | C26: 950 × 2 × 70 = 133,000
A27: Premium conversion rate | B27: 0.05 | C27: Freemium SaaS benchmark; held flat across all years
A28: Annual student churn rate | B28: 0.6 | C28: One app cycle per student; offset by new cohort each year
A29: Premium price ($/yr) | B29: 60 | C29: $4.99/mo; validated price point
A30: Universities Y1 | B30: 3 | C30: TAMU + 2 DFW schools; manageable for 2-person team
A31: Universities Y2 | B31: 10 | C31: Expand to top Texas pre-med schools
... A35: Student reach rate per org (ambassador) | B35: 0.25 | C35: Ambassador realistically reaches 1 in 4 active members
A36: ADVISOR DASHBOARD (launches Y4)
A37: Advisor dashboard price ($/yr/office) | B37: 5000 | C37: Below comparable advising SaaS tools ($8-15K); entry pricing
A38: Advisor dashboard close rate | B38: 0.15 | C38: Warm intro via ambassador network required
A39: Addressable university offices Y4 | B39: 20 | C39: Warm intros through ambassador relationships at 75 schools
A40: Addressable university offices Y5 | B40: 60 | C40: Scales with national university footprint
A41: OPERATING COSTS
A42: Y1 costs ($) | B42: 5839 | C42: Legal ($2.5K) + Apple Dev ($99) + Tools/infra ($1.6K) + Outreach/events ($1.5K)
A43: Y2 costs ($) | B43: 12350 | C43: Tools/infra ($2.6K) + Influencer/outreach ($2.75K) + Paid ads ($5K) + events/misc ($2K)
...

Sheet Clinic Revenue
A1: ClinicalHours — Clinic Revenue Build
A2: Metric | C2: Y1 (2025) | D2: Y2 (2026) | E2: Y3 (2027) | F2: Y4 (2028) | G2: Y5 (2029)
A3: ADDRESSABLE MARKET
A4: Addressable clinic sites | C4: =Assumptions!B8 -> 1250 | D4: =Assumptions!B8 -> 1250 | E4: =Assumptions!B9 -> 17600 | F4: =Assumptions!B9 -> 17600 | G4: =Assumptions!B9 -> 17600
A5: Close rate | C5: =Assumptions!B10 -> 0.01 | D5: =Assumptions!B11 -> 0.04 | E5: =Assumptions!B12 -> 0.03 | F5: =Assumptions!B13 -> 0.08 | G5: =Assumptions!B14 -> 0.1
A6: New clinic sites signed | C6: =ROUND(C4*C5,0) -> 13 | D6: =ROUND(D4*D5,0) -> 50 | E6: =ROUND(E4*E5,0) -> 528 | F6: =ROUND(F4*F5,0) -> 1408 | G6: =ROUND(G4*G5,0) -> 1760
A7: Churned sites (prior cumulative × 10%) | C7: =0 -> 0 | D7: =ROUND(C8*Assumptions!B15,0) -> 1 | E7: =ROUND(D8*Assumptions!B15,0) -> 6 | F7: =ROUND(E8*Assumptions!B15,0) -> 58 | G7: =ROUND(F8*Assumptions!B15,0) -> 193
A8: Cumulative active clinic sites | C8: =C6-C7 -> 13 | D8: =C8+D6-D7 -> 62 | E8: =D8+E6-E7 -> 584 | F8: =E8+F6-F7 -> 1934 | G8: =F8+G6-G7 -> 3501
A10: CLINIC REVENUE
A11: Price per site ($/yr) | C11: =Assumptions!B16 -> 750 | D11: =Assumptions!B16 -> 750 | E11: =Assumptions!B17 -> 1000 | F11: =Assumptions!B17 -> 1000 | G11: =Assumptions!B17 -> 1000
A12: Total Clinic Revenue ($) | C12: =C8*C11 -> 9750 | D12: =D8*D11 -> 46500 | E12: =E8*E11 -> 584000 | F12: =F8*F11 -> 1934000 | G12: =G8*G11 -> 3501000

Sheet Student Revenue
A1: ClinicalHours — Student Revenue Build
A2: Metric | C2: Y1 (2025) | D2: Y2 (2026) | E2: Y3 (2027) | F2: Y4 (2028) | G2: Y5 (2029)
A3: STUDENT FUNNEL
A4: Universities in ambassador program | C4: =Assumptions!B30 -> 3 | D4: =Assumptions!B31 -> 10 | E4: =Assumptions!B32 -> 30 | F4: =Assumptions!B33 -> 75 | G4: =Assumptions!B34 -> 150
A5: Students reached (univ × 70 members × 25% reach) | C5: =ROUND(C4*Assumptions!B25*Assumptions!B35,0) -> 53 | D5: =ROUND(D4*Assumptions!B25*Assumptions!B35,0) -> 175 | E5: =ROUND(E4*Assumptions!B25*Assumptions!B35,0) -> 525 | F5: =ROUND(F4*Assumptions!B25*Assumptions!B35,0) -> 1313 | G5: =ROUND(G4*Assumptions!B25*Assumptions!B35,0) -> 2625
A6: New premium subscribers (reached × 5% conversion) | C6: =ROUND(C5*Assumptions!B27,0) -> 3 | D6: =ROUND(D5*Assumptions!B27,0) -> 9 | E6: =ROUND(E5*Assumptions!B27,0) -> 26 | F6: =ROUND(F5*Assumptions!B27,0) -> 66 | G6: =ROUND(G5*Assumptions!B27,0) -> 131
A7: Churned subscribers (prior cumulative × 60%) | C7: =0 -> 0 | D7: =ROUND(C8*Assumptions!B28,0) -> 2 | E7: =ROUND(D8*Assumptions!B28,0) -> 6 | F7: =ROUND(E8*Assumptions!B28,0) -> 18 | G7: =ROUND(F8*Assumptions!B28,0) -> 47
A8: Cumulative premium subscribers | C8: =C6-C7 -> 3 | D8: =C8+D6-D7 -> 10 | E8: =D8+E6-E7 -> 30 | F8: =E8+F6-F7 -> 78 | G8: =F8+G6-G7 -> 162
A10: ADVISOR DASHBOARD (launches Y4)
A11: Addressable university offices | C11: =0 -> 0 | D11: =0 -> 0 | E11: =0 -> 0 | F11: =Assumptions!B39 -> 20 | G11: =Assumptions!B40 -> 60
A12: New offices closed (× 15%) | C12: =ROUND(C11*Assumptions!B38,0) -> 0 | D12: =ROUND(D11*Assumptions!B38,0) -> 0 | E12: =ROUND(E11*Assumptions!B38,0) -> 0 | F12: =ROUND(F11*Assumptions!B38,0) -> 3 | G12: =ROUND(G11*Assumptions!B38,0) -> 9
A13: Cumulative active university offices | C13: =C12 -> 0 | D13: =C13+D12 -> 0 | E13: =D13+E12 -> 0 | F13: =E13+F12 -> 3 | G13: =F13+G12 -> 12
A15: STUDENT + ADVISOR REVENUE
A16: Premium price ($/yr) | C16: =Assumptions!B29 -> 60 | D16: =Assumptions!B29 -> 60 | E16: =Assumptions!B29 -> 60 | F16: =Assumptions!B29 -> 60 | G16: =Assumptions!B29 -> 60
A17: Student Premium Revenue ($) | C17: =C8*C16 -> 180 | D17: =D8*D16 -> 600 | E17: =E8*E16 -> 1800 | F17: =F8*F16 -> 4680 | G17: =G8*G16 -> 9720
A18: Advisor Dashboard Revenue ($) | C18: =C13*Assumptions!B37 -> 0 | D18: =D13*Assumptions!B37 -> 0 | E18: =E13*Assumptions!B37 -> 0 | F18: =F13*Assumptions!B37 -> 15000 | G18: =G13*Assumptions!B37 -> 60000
A19: Total Student-Side Revenue ($) | C19: =C17+C18 -> 180 | D19: =D17+D18 -> 600 | E19: =E17+E18 -> 1800 | F19: =F17+F18 -> 19680 | G19: =G17+G18 -> 69720

Sheet Summary
A1: ClinicalHours — 5-Year Financial Summary
A2: Metric | C2: Y1 (2025) | D2: Y2 (2026) | E2: Y3 (2027) | F2: Y4 (2028) | G2: Y5 (2029)
A3: MARKET SIZING (for reference)
A4: TAM (combined) | C4: =Assumptions!B4 -> 24900000
A5: SAM (combined) | C5: =Assumptions!B5 -> 4400000
A6: SOM (Texas Year 1) | C6: =Assumptions!B6 -> 619200
A8: REVENUE
A9: Clinic Revenue ($) | C9: ='Clinic Revenue'!C12 -> 9750 | D9: ='Clinic Revenue'!D12 -> 46500 | E9: ='Clinic Revenue'!E12 -> 584000 | F9: ='Clinic Revenue'!F12 -> 1934000 | G9: ='Clinic Revenue'!G12 -> 3501000
A10: Student Premium Revenue ($) | C10: ='Student Revenue'!C17 -> 180 | D10: ='Student Revenue'!D17 -> 600 | E10: ='Student Revenue'!E17 -> 1800 | F10: ='Student Revenue'!F17 -> 4680 | G10: ='Student Revenue'!G17 -> 9720
A11: Advisor Dashboard Revenue ($) | C11: ='Student Revenue'!C18 -> 0 | D11: ='Student Revenue'!D18 -> 0 | E11: ='Student Revenue'!E18 -> 0 | F11: ='Student Revenue'!F18 -> 15000 | G11: ='Student Revenue'!G18 -> 60000
A12: TOTAL REVENUE ($) | C12: =C9+C10+C11 -> 9930 | D12: =D9+D10+D11 -> 47100 | E12: =E9+E10+E11 -> 585800 | F12: =F9+F10+F11 -> 1953680 | G12: =G9+G10+G11 -> 3570720
A14: COSTS & NET INCOME
A15: Operating Costs ($) | C15: =Assumptions!B42 -> 5839 | D15: =Assumptions!B43 -> 12350 | E15: =Assumptions!B44 -> 32400 | F15: =Assumptions!B45 -> 76000 | G15: =Assumptions!B46 -> 98000
A16: NET INCOME ($) | C16: =C12-C15 -> 4091 | D16: =D12-D15 -> 34750 | E16: =E12-E15 -> 553400 | F16: =F12-F15 -> 1877680 | G16: =G12-G15 -> 3472720
A18: KEY METRICS
A19: Active Clinic Sites | C19: ='Clinic Revenue'!C8 -> 13 | D19: ='Clinic Revenue'!D8 -> 62 | E19: ='Clinic Revenue'!E8 -> 584 | F19: ='Clinic Revenue'!F8 -> 1934 | G19: ='Clinic Revenue'!G8 -> 3501
A20: Premium Student Subscribers | C20: ='Student Revenue'!C8 -> 3 | D20: ='Student Revenue'!D8 -> 10 | E20: ='Student Revenue'!E8 -> 30 | F20: ='Student Revenue'!F8 -> 78 | G20: ='Student Revenue'!G8 -> 162
A21: University Advising Offices | C21: ='Student Revenue'!C13 -> 0 | D21: ='Student Revenue'!D13 -> 0 | E21: ='Student Revenue'!E13 -> 0 | F21: ='Student Revenue'!F13 -> 3 | G21: ='Student Revenue'!G13 -> 12
